Workbook

Sheet Qo‘llanma
A1: SHOKALON — videodarslar katalogi, 8-versiya
A2: Tayyorlangan sana | B2: 2026-10-17
A3: Nima bor | B3: 33 bob, 253 kichik mavzu (Mundarija); 312 ta video (Katalog) — ilovadagi barcha darslar shu yerda kod va Video ID bilan; rad etilgan havolalar; bob bo‘yicha qamrov; audit va loyihadan chetga chiqishlar.
A5: Mavzu kodi | B5: BB.CC.TT — BB: bo‘lim (01–13), CC: bob (01–33, butun kurs bo‘yicha), TT: kichik mavzu. Masalan 03.11.06 = III bo‘lim, 11-bob, 6-mavzu (CBD). Kodlar mundarija matni o‘zgarsa ham o‘zgarmaydi.
A6: Video ID | B6: V001, V002 … — topilish tartibida beriladi va hech qachon almashtirilmaydi. V001–V013 — 2026-10-11 dagi oldingi ish (saqlandi).
A7: Fayl nomi | B7: SHK_{kod nuqtasiz}_{Video ID}_{variant}.srt. Masalan: SHK_031106_V004_ORIGINAL.srt va SHK_031106_V004_UZ-LATIN.srt. Bir video bir nechta mavzuga tegsa, fayl faqat asosiy kod bilan nomlanadi.
A8: Subtitr variantlari | B8: ORIGINAL (muallif subtitri), ASR-EN (YouTube avtomatik), UZ-LATIN, UZ-LATIN-v2 … Versiya raqami faqat oshadi.
A10: Tekshiruv holatlari
A11: Metadata tekshirilgan (YouTube sahifasi) | B11: Nomi, kanali va nashr sanasi YouTube sahifasidan olindi va qidiruv natijasidagi nom bilan mos keldi. Video ko‘rilmagan.
A12: Metadata tekshirilgan (ikkilamchi sahifa) | B12: Ma’lumot Tom Wade MD saytidagi joylashtirilgan video sahifasidan olingan. Video ko‘rilmagan.
A13: Metadata qisman | B13: Faqat qidiruv natijasi bor; kanal yoki mazmun tasdiqlanmagan.
A14: Havola tekshirilgan (oEmbed, GitHub serveri) | B14: Video mavjud, ochiq; nomi va kanali YouTube’ning rasmiy oEmbed javobidan. Subtitr va O‘zbekistonda ochilishi tekshirilmagan. Video ko‘rilmagan.
A15: Ishlamaydi | B15: Server tekshiruvida video ochilmadi. Qator saqlanadi (ID o‘zgarmasin), lekin qamrovga kirmaydi.
A16: Mundarija holatlari | B16: Mavjud va tekshirilgan · Mavjud, lekin tekshirilmagan · Qisman to‘ldirilgan · Yetishmaydi · Takroriy · Yangilash kerak. Hech bir video hali to‘liq ko‘rilmagani uchun “Mavjud va tekshirilgan” holati hozircha yo‘q.
A18: Siz to‘ldiradigan kataklar | B18: Sariq kataklar: Katalogdagi 6 ta baho ustuni (0–5), Subtitr turi va Izoh. Ballni faqat videoni ko‘rgach qo‘ying; 6 tasi to‘lsa, jami avtomatik hisoblanadi.
A19: Baho mezonlari (0–5) | B19: Mavzuga moslik · Tibbiy ishonchlilik · Amaliy demonstratsiya · Tushuntirish sifati · O‘quv darajasi · Vizual aniqlik. Jami 30.
A21: Cheklovlar | B21: Davomiylik bo‘sh yoki “>” bilan yozilgan joylarda YouTube sahifasi davomiylikni bermadi; “>” = oxirgi bob belgisigacha bo‘lgan vaqt. Subtitr borligi hech bir video uchun tekshirilmadi (sahifa ko‘rsatmadi). Litsenziya turi tekshirilmadi.
A22: Papka tuzilmasi (taklif) | B22: 01_CURRICULUM · 02_VIDEO_CATALOG (shu fayl) · 03_SUBTITLES_ORIGINAL · 04_SUBTITLES_TRANSLATED · 05_SUBTITLE_QA · 06_ULTRASOUND_ATLAS · 07_TESTS · 08_PRESENTATIONS · 09_REFERENCES · 10_RELEASES. Ilovaga (Dual Replay) katalog keyinroq shu fayldan avtomatik yasaladigan JSON sifatida kiradi.

Sheet Mundarija
A1: Kod | B1: Bo‘lim | C1: Bob | D1: Kichik mavzu | E1: Videolar soni | F1: Qisman (audit) | G1: Takror (audit) | H1: Holat | I1: Audit izohi
A2: 01.01.01 | B2: I. ULTRATOVUSH FIZIKASI VA APPARAT BILAN ISHLASH | C2: 1-bob. Ultratovush fizikasi | D2: 1.1. Tovush va ultratovushning tabiati, chastota, davr, amplituda va to‘lqin uzunligi. | E2: =COUNTIFS(Katalog!$B:$B,A2,Katalog!$Q:$Q,"<>Ishlamaydi*")+COUNTIFS(Katalog!$C:$C,"*"&A2&"*",Katalog!$Q:$Q,"<>Ishlamaydi*") -> 3 | H2: =IF(G2<>"","Takroriy",IF(E2=0,"Yetishmaydi",IF(F2="ha","Qisman to‘ldirilgan","Mavjud, lekin tekshirilmagan"))) -> Mavjud, lekin tekshirilmagan
A3: 01.01.02 | B3: I. ULTRATOVUSH FIZIKASI VA APPARAT BILAN ISHLASH | C3: 1-bob. Ultratovush fizikasi | D3: 1.2. Tovush tezligi, akustik impedans va to‘qimalar chegarasida aks etish. | E3: =COUNTIFS(Katalog!$B:$B,A3,Katalog!$Q:$Q,"<>Ishlamaydi*")+COUNTIFS(Katalog!$C:$C,"*"&A3&"*",Katalog!$Q:$Q,"<>Ishlamaydi*") -> 3 | H3: =IF(G3<>"","Takroriy",IF(E3=0,"Yetishmaydi",IF(F3="ha","Qisman to‘ldirilgan","Mavjud, lekin tekshirilmagan"))) -> Mavjud, lekin tekshirilmagan
A4: 01.01.03 | B4: I. ULTRATOVUSH FIZIKASI VA APPARAT BILAN ISHLASH | C4: 1-bob. Ultratovush fizikasi | D4: 1.3. Refleksiya, refraksiya, sochilish, diffraksiya va absorbsiya. | E4: =COUNTIFS(Katalog!$B:$B,A4,Katalog!$Q:$Q,"<>Ishlamaydi*")+COUNTIFS(Katalog!$C:$C,"*"&A4&"*",Katalog!$Q:$Q,"<>Ishlamaydi*") -> 2 | H4: =IF(G4<>"","Takroriy",IF(E4=0,"Yetishmaydi",IF(F4="ha","Qisman to‘ldirilgan","Mavjud, lekin tekshirilmagan"))) -> Mavjud, lekin tekshirilmagan
A5: 01.01.04 | B5: I. ULTRATOVUSH FIZIKASI VA APPARAT BILAN ISHLASH | C5: 1-bob. Ultratovush fizikasi | D5: 1.4. Attenuatsiya, chuqurlik va chastota o‘rtasidagi bog‘liqlik. | E5: =COUNTIFS(Katalog!$B:$B,A5,Katalog!$Q:$Q,"<>Ishlamaydi*")+COUNTIFS(Katalog!$C:$C,"*"&A5&"*",Katalog!$Q:$Q,"<>Ishlamaydi*") -> 1 | H5: =IF(G5<>"","Takroriy",IF(E5=0,"Yetishmaydi",IF(F5="ha","Qisman to‘ldirilgan","Mavjud, lekin tekshirilmagan"))) -> Mavjud, lekin tekshirilmagan
A6: 01.01.05 | B6: I. ULTRATOVUSH FIZIKASI VA APPARAT BILAN ISHLASH | C6: 1-bob. Ultratovush fizikasi | D6: 1.5. Echogenlik, akustik interfeyslar va tasvir hosil bo‘lishining fizik asoslari. | E6: =COUNTIFS(Katalog!$B:$B,A6,Katalog!$Q:$Q,"<>Ishlamaydi*")+COUNTIFS(Katalog!$C:$C,"*"&A6&"*",Katalog!$Q:$Q,"<>Ishlamaydi*") -> 1 | F6: ha | H6: =IF(G6<>"","Takroriy",IF(E6=0,"Yetishmaydi",IF(F6="ha","Qisman to‘ldirilgan","Mavjud, lekin tekshirilmagan"))) -> Qisman to‘ldirilgan
A7: 01.02.01 | B7: I. ULTRATOVUSH FIZIKASI VA APPARAT BILAN ISHLASH | C7: 2-bob. UZI apparati va datchiklar | D7: 2.1. Pyezoelektrik effekt va transduserning ishlash prinsipi. | E7: =COUNTIFS(Katalog!$B:$B,A7,Katalog!$Q:$Q,"<>Ishlamaydi*")+COUNTIFS(Katalog!$C:$C,"*"&A7&"*",Katalog!$Q:$Q,"<>Ishlamaydi*") -> 1 | H7: =IF(G7<>"","Takroriy",IF(E7=0,"Yetishmaydi",IF(F7="ha","Qisman to‘ldirilgan","Mavjud, lekin tekshirilmagan"))) -> Mavjud, lekin tekshirilmagan
A8: 01.02.02 | B8: I. ULTRATOVUSH FIZIKASI VA APPARAT BILAN ISHLASH | C8: 2-bob. UZI apparati va datchiklar | D8: 2.2. Konveks, chiziqli, sektor/fazalangan va endokavitar datchiklar. | E8: =COUNTIFS(Katalog!$B:$B,A8,Katalog!$Q:$Q,"<>Ishlamaydi*")+COUNTIFS(Katalog!$C:$C,"*"&A8&"*",Katalog!$Q:$Q,"<>Ishlamaydi*") -> 3 | H8: =IF(G8<>"","Takroriy",IF(E8=0,"Yetishmaydi",IF(F8="ha","Qisman to‘ldirilgan","Mavjud, lekin tekshirilmagan"))) -> Mavjud, lekin tekshirilmagan
A9: 01.02.03 | B9: I. ULTRATOVUSH FIZIKASI VA APPARAT BILAN ISHLASH | C9: 2-bob. UZI apparati va datchiklar | D9: 2.3. Datchik chastotasi va tekshiruvga mos datchikni tanlash. | E9: =COUNTIFS(Katalog!$B:$B,A9,Katalog!$Q:$Q,"<>Ishlamaydi*")+COUNTIFS(Katalog!$C:$C,"*"&A9&"*",Katalog!$Q:$Q,"<>Ishlamaydi*") -> 1 | F9: ha | H9: =IF(G9<>"","Takroriy",IF(E9=0,"Yetishmaydi",IF(F9="ha","Qisman to‘ldirilgan","Mavjud, lekin tekshirilmagan"))) -> Qisman to‘ldirilgan
A10: 01.02.04 | B10: I. ULTRATOVUSH FIZIKASI VA APPARAT BILAN ISHLASH | C10: 2-bob. UZI apparati va datchiklar | D10: 2.4. Eksenel, lateral va elevatsion rezolyutsiya. | E10: =COUNTIFS(Katalog!$B:$B,A10,Katalog!$Q:$Q,"<>Ishlamaydi*")+COUNTIFS(Katalog!$C:$C,"*"&A10&"*",Katalog!$Q:$Q,"<>Ishlamaydi*") -> 4 | H10: =IF(G10<>"","Takroriy",IF(E10=0,"Yetishmaydi",IF(F10="ha","Qisman to‘ldirilgan","Mavjud, lekin tekshirilmagan"))) -> Mavjud, lekin tekshirilmagan | I10: Atama: “eksenel” → “aksial” rezolyutsiya
A11: 01.02.05 | B11: I. ULTRATOVUSH FIZIKASI VA APPARAT BILAN ISHLASH | C11: 2-bob. UZI apparati va datchiklar | D11: 2.5. B-rejim, M-rejim va tasvirni qayta ishlash. | E11: =COUNTIFS(Katalog!$B:$B,A11,Katalog!$Q:$Q,"<>Ishlamaydi*")+COUNTIFS(Katalog!$C:$C,"*"&A11&"*",Katalog!$Q:$Q,"<>Ishlamaydi*") -> 3 | H11: =IF(G11<>"","Takroriy",IF(E11=0,"Yetishmaydi",IF(F11="ha","Qisman to‘ldirilgan","Mavjud, lekin tekshirilmagan"))) -> Mavjud, lekin tekshirilmagan
A12: 01.02.06 | B12: I. ULTRATOVUSH FIZIKASI VA APPARAT BILAN ISHLASH | C12: 2-bob. UZI apparati va datchiklar | D12: 2.6. Panoramik tasvir, compound imaging, harmonic imaging va speklni kamaytirish. | E12: =COUNTIFS(Katalog!$B:$B,A12,Katalog!$Q:$Q,"<>Ishlamaydi*")+COUNTIFS(Katalog!$C:$C,"*"&A12&"*",Katalog!$Q:$Q,"<>Ishlamaydi*") -> 1 | F12: ha | H12: =IF(G12<>"","Takroriy",IF(E12=0,"Yetishmaydi",IF(F12="ha","Qisman to‘ldirilgan","Mavjud, lekin tekshirilmagan"))) -> Qisman to‘ldirilgan | I12: Atama: compound/harmonic imaging → kompaund va garmonik tasvirlash
A13: 01.02.07 | B13: I. ULTRATOVUSH FIZIKASI VA APPARAT BILAN ISHLASH | C13: 2-bob. UZI apparati va datchiklar | D13: 2.7. Datchiklarni tozalash, dezinfeksiya va infeksiya nazorati. | E13: =COUNTIFS(Katalog!$B:$B,A13,Katalog!$Q:$Q,"<>Ishlamaydi*")+COUNTIFS(Katalog!$C:$C,"*"&A13&"*",Katalog!$Q:$Q,"<>Ishlamaydi*") -> 2 | F13: ha | H13: =IF(G13<>"","Takroriy",IF(E13=0,"Yetishmaydi",IF(F13="ha","Qisman to‘ldirilgan","Mavjud, lekin tekshirilmagan"))) -> Qisman to‘ldirilgan
A14: 01.03.01 | B14: I. ULTRATOVUSH FIZIKASI VA APPARAT BILAN ISHLASH | C14: 3-bob. Tasvirni optimallashtirish | D14: 3.1. Gain va TGC. | E14: =COUNTIFS(Katalog!$B:$B,A14,Katalog!$Q:$Q,"<>Ishlamaydi*")+COUNTIFS(Katalog!$C:$C,"*"&A14&"*",Katalog!$Q:$Q,"<>Ishlamaydi*") -> 3 | H14: =IF(G14<>"","Takroriy",IF(E14=0,"Yetishmaydi",IF(F14="ha","Qisman to‘ldirilgan","Mavjud, lekin tekshirilmagan"))) -> Mavjud, lekin tekshirilmagan
A15: 01.03.02 | B15: I. ULTRATOVUSH FIZIKASI VA APPARAT BILAN ISHLASH | C15: 3-bob. Tasvirni optimallashtirish | D15: 3.2. Depth, fokus va ko‘rish maydoni. | E15: =COUNTIFS(Katalog!$B:$B,A15,Katalog!$Q:$Q,"<>Ishlamaydi*")+COUNTIFS(Katalog!$C:$C,"*"&A15&"*",Katalog!$Q:$Q,"<>Ishlamaydi*") -> 5 | H15: =IF(G15<>"","Takroriy",IF(E15=0,"Yetishmaydi",IF(F15="ha","Qisman to‘ldirilgan","Mavjud, lekin tekshirilmagan"))) -> Mavjud, lekin tekshirilmagan
A16: 01.03.03 | B16: I. ULTRATOVUSH FIZIKASI VA APPARAT BILAN ISHLASH | C16: 3-bob. Tasvirni optimallashtirish | D16: 3.3. Dynamic range, chastota, frame rate va tasvir tezligi. | E16: =COUNTIFS(Katalog!$B:$B,A16,Katalog!$Q:$Q,"<>Ishlamaydi*")+COUNTIFS(Katalog!$C:$C,"*"&A16&"*",Katalog!$Q:$Q,"<>Ishlamaydi*") -> 3 | H16: =IF(G16<>"","Takroriy",IF(E16=0,"Yetishmaydi",IF(F16="ha","Qisman to‘ldirilgan","Mavjud, lekin tekshirilmagan"))) -> Mavjud, lekin tekshirilmagan
A17: 01.03.04 | B17: I. ULTRATOVUSH FIZIKASI VA APPARAT BILAN ISHLASH | C17: 3-bob. Tasvirni optimallashtirish | D17: 3.4. Zoom, cine-loop, o‘lchash va tasvirni saqlash. | E17: =COUNTIFS(Katalog!$B:$B,A17,Katalog!$Q:$Q,"<>Ishlamaydi*")+COUNTIFS(Katalog!$C:$C,"*"&A17&"*",Katalog!$Q:$Q,"<>Ishlamaydi*") -> 1 | F17: ha | H17: =IF(G17<>"","Takroriy",IF(E17=0,"Yetishmaydi",IF(F17="ha","Qisman to‘ldirilgan","Mavjud, lekin tekshirilmagan"))) -> Qisman to‘ldirilgan
A18: 01.03.05 | B18: I. ULTRATOVUSH FIZIKASI VA APPARAT BILAN ISHLASH | C18: 3-bob. Tasvirni optimallashtirish | D18: 3.5. Turli a’zolar uchun boshlang‘ich sozlamalar. | E18: =COUNTIFS(Katalog!$B:$B,A18,Katalog!$Q:$Q,"<>Ishlamaydi*")+COUNTIFS(Katalog!$C:$C,"*"&A18&"*",Katalog!$Q:$Q,"<>Ishlamaydi*") -> 0 | H18: =IF(G18<>"","Takroriy",IF(E18=0,"Yetishmaydi",IF(F18="ha","Qisman to‘ldirilgan","Mavjud, lekin tekshirilmagan"))) -> Yetishmaydi
A19: 01.03.06 | B19: I. ULTRATOVUSH FIZIKASI VA APPARAT BILAN ISHLASH | C19: 3-bob. Tasvirni optimallashtirish | D19: 3.6. Texnik xatolar va tasvir sifatini nazorat qilish. | E19: =COUNTIFS(Katalog!$B:$B,A19,Katalog!$Q:$Q,"<>Ishlamaydi*")+COUNTIFS(Katalog!$C:$C,"*"&A19&"*",Katalog!$Q:$Q,"<>Ishlamaydi*") -> 1 | H19: =IF(G19<>"","Takroriy",IF(E19=0,"Yetishmaydi",IF(F19="ha","Qisman to‘ldirilgan","Mavjud, lekin tekshirilmagan"))) -> Mavjud, lekin tekshirilmagan
A20: 01.04.01 | B20: I. ULTRATOVUSH FIZIKASI VA APPARAT BILAN ISHLASH | C20: 4-bob. Ultratovush artefaktlari | D20: 4.1. Akustik soya va posterior akustik kuchayish. | E20: =COUNTIFS(Katalog!$B:$B,A20,Katalog!$Q:$Q,"<>Ishlamaydi*")+COUNTIFS(Katalog!$C:$C,"*"&A20&"*",Katalog!$Q:$Q,"<>Ishlamaydi*") -> 2 | H20: =IF(G20<>"","Takroriy",IF(E20=0,"Yetishmaydi",IF(F20="ha","Qisman to‘ldirilgan","Mavjud, lekin tekshirilmagan"))) -> Mavjud, lekin tekshirilmagan
A21: 01.04.02 | B21: I. ULTRATOVUSH FIZIKASI VA APPARAT BILAN ISHLASH | C21: 4-bob. Ultratovush artefaktlari | D21: 4.2. Reverberatsiya, kometa dumi va ring-down. | E21: =COUNTIFS(Katalog!$B:$B,A21,Katalog!$Q:$Q,"<>Ishlamaydi*")+COUNTIFS(Katalog!$C:$C,"*"&A21&"*",Katalog!$Q:$Q,"<>Ishlamaydi*") -> 1 | H21: =IF(G21<>"","Takroriy",IF(E21=0,"Yetishmaydi",IF(F21="ha","Qisman to‘ldirilgan","Mavjud, lekin tekshirilmagan"))) -> Mavjud, lekin tekshirilmagan
A22: 01.04.03 | B22: I. ULTRATOVUSH FIZIKASI VA APPARAT BILAN ISHLASH | C22: 4-bob. Ultratovush artefaktlari | D22: 4.3. Ko‘zgu artefakti va refraksiya. | E22: =COUNTIFS(Katalog!$B:$B,A22,Katalog!$Q:$Q,"<>Ishlamaydi*")+COUNTIFS(Katalog!$C:$C,"*"&A22&"*",Katalog!$Q:$Q,"<>Ishlamaydi*") -> 2 | F22: ha | H22: =IF(G22<>"","Takroriy",IF(E22=0,"Yetishmaydi",IF(F22="ha","Qisman to‘ldirilgan","Mavjud, lekin tekshirilmagan"))) -> Qisman to‘ldirilgan
A23: 01.04.04 | B23: I. ULTRATOVUSH FIZIKASI VA APPARAT BILAN ISHLASH | C23: 4-bob. Ultratovush artefaktlari | D23: 4.4. Yon lob, qalin kesim va anizotropiya artefaktlari. | E23: =COUNTIFS(Katalog!$B:$B,A23,Katalog!$Q:$Q,"<>Ishlamaydi*")+COUNTIFS(Katalog!$C:$C,"*"&A23&"*",Katalog!$Q:$Q,"<>Ishlamaydi*") -> 2 | F23: ha | H23: =IF(G23<>"","Takroriy",IF(E23=0,"Yetishmaydi",IF(F23="ha","Qisman to‘ldirilgan","Mavjud, lekin tekshirilmagan"))) -> Qisman to‘ldirilgan
A24: 01.04.05 | B24: I. ULTRATOVUSH FIZIKASI VA APPARAT BILAN ISHLASH | C24: 4-bob. Ultratovush artefaktlari | D24: 4.5. Doppler aliasing va boshqa Doppler artefaktlari. | E24: =COUNTIFS(Katalog!$B:$B,A24,Katalog!$Q:$Q,"<>Ishlamaydi*")+COUNTIFS(Katalog!$C:$C,"*"&A24&"*",Katalog!$Q:$Q,"<>Ishlamaydi*") -> 2 | H24: =IF(G24<>"","Takroriy",IF(E24=0,"Yetishmaydi",IF(F24="ha","Qisman to‘ldirilgan","Mavjud, lekin tekshirilmagan"))) -> Mavjud, lekin tekshirilmagan | I24: Tartib: Doppler artefakti 5-bob (Doppler asoslari)dan oldin keladi; 5-bob oxiriga ko‘chirish taklif etiladi
A25: 01.04.06 | B25: I. ULTRATOVUSH FIZIKASI VA APPARAT BILAN ISHLASH | C25: 4-bob. Ultratovush artefaktlari | D25: 4.6. Artefaktlarni patologiyadan farqlash va diagnostik ahamiyati. | E25: =COUNTIFS(Katalog!$B:$B,A25,Katalog!$Q:$Q,"<>Ishlamaydi*")+COUNTIFS(Katalog!$C:$C,"*"&A25&"*",Katalog!$Q:$Q,"<>Ishlamaydi*") -> 3 | H25: =IF(G25<>"","Takroriy",IF(E25=0,"Yetishmaydi",IF(F25="ha","Qisman to‘ldirilgan","Mavjud, lekin tekshirilmagan"))) -> Mavjud, lekin tekshirilmagan
A26: 01.05.01 | B26: I. ULTRATOVUSH FIZIKASI VA APPARAT BILAN ISHLASH | C26: 5-bob. Doppler ultratovush asoslari | D26: 5.1. Doppler effekti va Doppler tenglamasi. | E26: =COUNTIFS(Katalog!$B:$B,A26,Katalog!$Q:$Q,"<>Ishlamaydi*")+COUNTIFS(Katalog!$C:$C,"*"&A26&"*",Katalog!$Q:$Q,"<>Ishlamaydi*") -> 1 | H26: =IF(G26<>"","Takroriy",IF(E26=0,"Yetishmaydi",IF(F26="ha","Qisman to‘ldirilgan","Mavjud, lekin tekshirilmagan"))) -> Mavjud, lekin tekshirilmagan
A27: 01.05.02 | B27: I. ULTRATOVUSH FIZIKASI VA APPARAT BILAN ISHLASH | C27: 5-bob. Doppler ultratovush asoslari | D27: 5.2. Color Doppler va Power Doppler. | E27: =COUNTIFS(Katalog!$B:$B,A27,Katalog!$Q:$Q,"<>Ishlamaydi*")+COUNTIFS(Katalog!$C:$C,"*"&A27&"*",Katalog!$Q:$Q,"<>Ishlamaydi*") -> 2 | H27: =IF(G27<>"","Takroriy",IF(E27=0,"Yetishmaydi",IF(F27="ha","Qisman to‘ldirilgan","Mavjud, lekin tekshirilmagan"))) -> Mavjud, lekin tekshirilmagan
A28: 01.05.03 | B28: I. ULTRATOVUSH FIZIKASI VA APPARAT BILAN ISHLASH | C28: 5-bob. Doppler ultratovush asoslari | D28: 5.3. Pulsli spektral Doppler va uzluksiz to‘lqinli Doppler. | E28: =COUNTIFS(Katalog!$B:$B,A28,Katalog!$Q:$Q,"<>Ishlamaydi*")+COUNTIFS(Katalog!$C:$C,"*"&A28&"*",Katalog!$Q:$Q,"<>Ishlamaydi*") -> 1 | H28: =IF(G28<>"","Takroriy",IF(E28=0,"Yetishmaydi",IF(F28="ha","Qisman to‘ldirilgan","Mavjud, lekin tekshirilmagan"))) -> Mavjud, lekin tekshirilmagan
A29: 01.05.04 | B29: I. ULTRATOVUSH FIZIKASI VA APPARAT BILAN ISHLASH | C29: 5-bob. Doppler ultratovush asoslari | D29: 5.4. PRF, scale, wall filter, gain va sample volume. | E29: =COUNTIFS(Katalog!$B:$B,A29,Katalog!$Q:$Q,"<>Ishlamaydi*")+COUNTIFS(Katalog!$C:$C,"*"&A29&"*",Katalog!$Q:$Q,"<>Ishlamaydi*") -> 1 | H29: =IF(G29<>"","Takroriy",IF(E29=0,"Yetishmaydi",IF(F29="ha","Qisman to‘ldirilgan","Mavjud, lekin tekshirilmagan"))) -> Mavjud, lekin tekshirilmagan
A30: 01.05.05 | B30: I. ULTRATOVUSH FIZIKASI VA APPARAT BILAN ISHLASH | C30: 5-bob. Doppler ultratovush asoslari | D30: 5.5. Doppler burchagi va burchak korreksiyasi. | E30: =COUNTIFS(Katalog!$B:$B,A30,Katalog!$Q:$Q,"<>Ishlamaydi*")+COUNTIFS(Katalog!$C:$C,"*"&A30&"*",Katalog!$Q:$Q,"<>Ishlamaydi*") -> 1 | F30: ha | H30: =IF(G30<>"","Takroriy",IF(E30=0,"Yetishmaydi",IF(F30="ha","Qisman to‘ldirilgan","Mavjud, lekin tekshirilmagan"))) -> Qisman to‘ldirilgan
A31: 01.05.06 | B31: I. ULTRATOVUSH FIZIKASI VA APPARAT BILAN ISHLASH | C31: 5-bob. Doppler ultratovush asoslari | D31: 5.6. Tezlik, RI, PI va boshqa gemodinamik ko‘rsatkichlar. | E31: =COUNTIFS(Katalog!$B:$B,A31,Katalog!$Q:$Q,"<>Ishlamaydi*")+COUNTIFS(Katalog!$C:$C,"*"&A31&"*",Katalog!$Q:$Q,"<>Ishlamaydi*") -> 3 | H31: =IF(G31<>"","Takroriy",IF(E31=0,"Yetishmaydi",IF(F31="ha","Qisman to‘ldirilgan","Mavjud, lekin tekshirilmagan"))) -> Mavjud, lekin tekshirilmagan
A32: 01.05.07 | B32: I. ULTRATOVUSH FIZIKASI VA APPARAT BILAN ISHLASH | C32: 5-bob. Doppler ultratovush asoslari | D32: 5.7. Past oqimli qon tomirlarini tekshirish va Doppler xatolari. | E32: =COUNTIFS(Katalog!$B:$B,A32,Katalog!$Q:$Q,"<>Ishlamaydi*")+COUNTIFS(Katalog!$C:$C,"*"&A32&"*",Katalog!$Q:$Q,"<>Ishlamaydi*") -> 1 | F32: ha | G32: 01.04.05 bilan qisman takror (Doppler xatolari) | H32: =IF(G32<>"","Takroriy",IF(E32=0,"Yetishmaydi",IF(F32="ha","Qisman to‘ldirilgan","Mavjud, lekin tekshirilmagan"))) -> Takroriy
A33: 01.06.01 | B33: I. ULTRATOVUSH FIZIKASI VA APPARAT BILAN ISHLASH | C33: 6-bob. Biologik xavfsizlik | D33: 6.1. Ultratovushning termal va mexanik bioeffektlari. | E33: =COUNTIFS(Katalog!$B:$B,A33,Katalog!$Q:$Q,"<>Ishlamaydi*")+COUNTIFS(Katalog!$C:$C,"*"&A33&"*",Katalog!$Q:$Q,"<>Ishlamaydi*") -> 1 | H33: =IF(G33<>"","Takroriy",IF(E33=0,"Yetishmaydi",IF(F33="ha","Qisman to‘ldirilgan","Mavjud, lekin tekshirilmagan"))) -> Mavjud, lekin tekshirilmagan
A34: 01.06.02 | B34: I. ULTRATOVUSH FIZIKASI VA APPARAT BILAN ISHLASH | C34: 6-bob. Biologik xavfsizlik | D34: 6.2. Thermal Index (TI) va Mechanical Index (MI). | E34: =COUNTIFS(Katalog!$B:$B,A34,Katalog!$Q:$Q,"<>Ishlamaydi*")+COUNTIFS(Katalog!$C:$C,"*"&A34&"*",Katalog!$Q:$Q,"<>Ishlamaydi*") -> 2 | H34: =IF(G34<>"","Takroriy",IF(E34=0,"Yetishmaydi",IF(F34="ha","Qisman to‘ldirilgan","Mavjud, lekin tekshirilmagan"))) -> Mavjud, lekin tekshirilmagan
A35: 01.06.03 | B35: I. ULTRATOVUSH FIZIKASI VA APPARAT BILAN ISHLASH | C35: 6-bob. Biologik xavfsizlik | D35: 6.3. ALARA tamoyili va tekshiruv davomiyligi. | E35: =COUNTIFS(Katalog!$B:$B,A35,Katalog!$Q:$Q,"<>Ishlamaydi*")+COUNTIFS(Katalog!$C:$C,"*"&A35&"*",Katalog!$Q:$Q,"<>Ishlamaydi*") -> 1 | H35: =IF(G35<>"","Takroriy",IF(E35=0,"Yetishmaydi",IF(F35="ha","Qisman to‘ldirilgan","Mavjud, lekin tekshirilmagan"))) -> Mavjud, lekin tekshirilmagan
A36: 01.06.04 | B36: I. ULTRATOVUSH FIZIKASI VA APPARAT BILAN ISHLASH | C36: 6-bob. Biologik xavfsizlik | D36: 6.4. Homiladorlar va bolalarda xavfsiz tekshiruv. | E36: =COUNTIFS(Katalog!$B:$B,A36,Katalog!$Q:$Q,"<>Ishlamaydi*")+COUNTIFS(Katalog!$C:$C,"*"&A36&"*",Katalog!$Q:$Q,"<>Ishlamaydi*") -> 1 | F36: ha | H36: =IF(G36<>"","Takroriy",IF(E36=0,"Yetishmaydi",IF(F36="ha","Qisman to‘ldirilgan","Mavjud, lekin tekshirilmagan"))) -> Qisman to‘ldirilgan
A37: 01.06.05 | B37: I. ULTRATOVUSH FIZIKASI VA APPARAT BILAN ISHLASH | C37: 6-bob. Biologik xavfsizlik | D37: 6.5. Datchik gigiyenasi va infeksiya profilaktikasi. | E37: =COUNTIFS(Katalog!$B:$B,A37,Katalog!$Q:$Q,"<>Ishlamaydi*")+COUNTIFS(Katalog!$C:$C,"*"&A37&"*",Katalog!$Q:$Q,"<>Ishlamaydi*") -> 1 | F37: ha | G37: 01.02.07 bilan takror (datchik gigiyenasi). Bittasida qoldirib, ikkinchisida havola berish taklif etiladi | H37: =IF(G37<>"","Takroriy",IF(E37=0,"Yetishmaydi",IF(F37="ha","Qisman to‘ldirilgan","Mavjud, lekin tekshirilmagan"))) -> Takroriy
A38: 01.06.06 | B38: I. ULTRATOVUSH FIZIKASI VA APPARAT BILAN ISHLASH | C38: 6-bob. Biologik xavfsizlik | D38: 6.6. Kontrastli UZI xavfsizligi va maxsus tayyorgarlik talablari. | E38: =COUNTIFS(Katalog!$B:$B,A38,Katalog!$Q:$Q,"<>Ishlamaydi*")+COUNTIFS(Katalog!$C:$C,"*"&A38&"*",Katalog!$Q:$Q,"<>Ishlamaydi*") -> 1 | F38: ha | H38: =IF(G38<>"","Takroriy",IF(E38=0,"Yetishmaydi",IF(F38="ha","Qisman to‘ldirilgan","Mavjud, lekin tekshirilmagan"))) -> Qisman to‘ldirilgan | I38: Kontrast fizikasi 31-bobda; o‘zaro havola kerak
A39: 02.07.01 | B39: II. TEKSHIRUV METODIKASI VA DIAGNOSTIK TAFAKKUR | C39: 7-bob. Bemorni tekshiruvga tayyorlash | D39: 7.1. Anamnez, klinik savol va yo‘llanmani tahlil qilish. | E39: =COUNTIFS(Katalog!$B:$B,A39,Katalog!$Q:$Q,"<>Ishlamaydi*")+COUNTIFS(Katalog!$C:$C,"*"&A39&"*",Katalog!$Q:$Q,"<>Ishlamaydi*") -> 0 | H39: =IF(G39<>"","Takroriy",IF(E39=0,"Yetishmaydi",IF(F39="ha","Qisman to‘ldirilgan","Mavjud, lekin tekshirilmagan"))) -> Yetishmaydi
A40: 02.07.02 | B40: II. TEKSHIRUV METODIKASI VA DIAGNOSTIK TAFAKKUR | C40: 7-bob. Bemorni tekshiruvga tayyorlash | D40: 7.2. Qorin bo‘shlig‘i tekshiruvi uchun tayyorgarlik. | E40: =COUNTIFS(Katalog!$B:$B,A40,Katalog!$Q:$Q,"<>Ishlamaydi*")+COUNTIFS(Katalog!$C:$C,"*"&A40&"*",Katalog!$Q:$Q,"<>Ishlamaydi*") -> 1 | H40: =IF(G40<>"","Takroriy",IF(E40=0,"Yetishmaydi",IF(F40="ha","Qisman to‘ldirilgan","Mavjud, lekin tekshirilmagan"))) -> Mavjud, lekin tekshirilmagan
...

Sheet Qidiruv navbati
A1: Kod | B1: Kichik mavzu | C1: Videolar | D1: Holat | E1: Inglizcha qidiruv kalit so‘zlari | F1: Oxirgi qidiruv
A2: 01.01.05 | B2: 1.5. Echogenlik, akustik interfeyslar va tasvir hosil bo‘lishining fizik asoslari. | C2: 1 | D2: Qisman — qo‘shimcha qidiruv kerak | E2: echogenicity acoustic interface image formation ultrasound physics | F2: 2026-10-17
A3: 01.02.03 | B3: 2.3. Datchik chastotasi va tekshiruvga mos datchikni tanlash. | C3: 1 | D3: Qisman — qo‘shimcha qidiruv kerak | E3: choosing ultrasound transducer frequency; probe selection linear curvilinear phased array | F3: 2026-10-17
A4: 01.02.06 | B4: 2.6. Panoramik tasvir, compound imaging, harmonic imaging va speklni kamaytirish. | C4: 1 | D4: Qisman — qo‘shimcha qidiruv kerak | E4: spatial compound imaging ultrasound; panoramic extended field of view ultrasound; speckle reduction | F4: 2026-10-17
A5: 01.02.07 | B5: 2.7. Datchiklarni tozalash, dezinfeksiya va infeksiya nazorati. | C5: 2 | D5: Qisman — qo‘shimcha qidiruv kerak | E5: transducer reprocessing high level disinfection endocavity probe guideline | F5: 2026-10-17
A6: 01.03.04 | B6: 3.4. Zoom, cine-loop, o‘lchash va tasvirni saqlash. | C6: 1 | D6: Qisman — qo‘shimcha qidiruv kerak | E6: ultrasound cine loop zoom measurement calipers image storage | F6: 2026-10-17
A7: 01.03.05 | B7: 3.5. Turli a’zolar uchun boshlang‘ich sozlamalar. | C7: 0 | D7: Qayta qidirish kerak | E7: ultrasound presets abdominal obstetric small parts; knobology presets | F7: 2026-10-17
A8: 01.04.03 | B8: 4.3. Ko‘zgu artefakti va refraksiya. | C8: 2 | D8: Qisman — qo‘shimcha qidiruv kerak | E8: mirror image artifact ultrasound; refraction artifact; edge shadowing | F8: 2026-10-17
A9: 01.04.04 | B9: 4.4. Yon lob, qalin kesim va anizotropiya artefaktlari. | C9: 2 | D9: Qisman — qo‘shimcha qidiruv kerak | E9: side lobe artifact; slice thickness artifact; anisotropy tendon ultrasound | F9: 2026-10-17
A10: 01.05.05 | B10: 5.5. Doppler burchagi va burchak korreksiyasi. | C10: 1 | D10: Qisman — qo‘shimcha qidiruv kerak | E10: Doppler angle correction 60 degrees; insonation angle velocity error | F10: 2026-10-17
A11: 01.05.07 | B11: 5.7. Past oqimli qon tomirlarini tekshirish va Doppler xatolari. | C11: 1 | D11: Qisman — qo‘shimcha qidiruv kerak
A12: 01.06.04 | B12: 6.4. Homiladorlar va bolalarda xavfsiz tekshiruv. | C12: 1 | D12: Qisman — qo‘shimcha qidiruv kerak | E12: ultrasound safety pregnancy ALARA obstetric thermal index; neonatal ultrasound safety | F12: 2026-10-17
A13: 01.06.05 | B13: 6.5. Datchik gigiyenasi va infeksiya profilaktikasi. | C13: 1 | D13: Qisman — qo‘shimcha qidiruv kerak
A14: 01.06.06 | B14: 6.6. Kontrastli UZI xavfsizligi va maxsus tayyorgarlik talablari. | C14: 1 | D14: Qisman — qo‘shimcha qidiruv kerak | E14: contrast enhanced ultrasound safety microbubble contraindications | F14: 2026-10-17
A15: 02.07.01 | B15: 7.1. Anamnez, klinik savol va yo‘llanmani tahlil qilish. | C15: 0 | D15: Qayta qidirish kerak | E15: clinical question ultrasound request; patient history before ultrasound; referral | F15: 2026-10-17
A16: 02.07.06 | B16: 7.6. Tekshiruv cheklovlari va yetarli bo‘lmagan vizualizatsiyani qayd etish. | C16: 0 | D16: Qayta qidirish kerak | E16: limited ultrasound exam documentation suboptimal visualization reporting limitations | F16: 2026-10-17
A17: 02.08.02 | B17: 8.2. Bo‘ylama, ko‘ndalang va qiya tekisliklar. | C17: 3 | D17: Qisman — qo‘shimcha qidiruv kerak | E17: longitudinal transverse oblique ultrasound planes; sagittal coronal scanning planes | F17: 2026-10-17
A18: 02.08.05 | B18: 8.5. O‘lchash xatolari va takrorlanuvchanlik. | C18: 0 | D18: Qayta qidirish kerak | E18: ultrasound measurement error calipers; interobserver variability sonography | F18: 2026-10-17
A19: 02.09.01 | B19: 9.1. Normal anatomiyani patologiyadan farqlash. | C19: 1 | D19: Qisman — qo‘shimcha qidiruv kerak | E19: normal versus abnormal ultrasound images approach | F19: 2026-10-17
A20: 02.09.06 | B20: 9.6. Cheklovlar, tasodifiy topilmalar va shoshilinch belgilar. | C20: 0 | D20: Qayta qidirish kerak | E20: incidental findings ultrasound; critical results communication radiology; urgent ultrasound findings | F20: 2026-10-17
A21: 03.11.05 | B21: 11.5. Intrahepatik va ekstrahepatik o‘t yo‘llari kengayishi. | C21: 0 | D21: Qayta qidirish kerak | E21: biliary dilatation ultrasound intrahepatic extrahepatic ducts; double duct sign | F21: 2026-10-17
A22: 03.11.07 | B22: 11.7. Mexanik sariqlikning sonografik sabablari. | C22: 0 | D22: Qayta qidirish kerak | E22: obstructive jaundice ultrasound causes choledocholithiasis cholangiocarcinoma | F22: 2026-10-17
A23: 03.11.08 | B23: 11.8. O‘t yo‘llari kasalliklarida differensial diagnostika. | C23: 0 | D23: Qayta qidirish kerak | E23: biliary disease differential diagnosis ultrasound; cholangitis; Mirizzi syndrome | F23: 2026-10-17
A24: 03.12.01 | B24: 12.1. Normal anatomiya va vizualizatsiya usullari. | C24: 2 | D24: Qisman — qo‘shimcha qidiruv kerak | E24: pancreas ultrasound anatomy landmarks splenic vein; how to see pancreas | F24: 2026-10-17
A25: 03.12.03 | B25: 12.3. Psevdokista va boshqa suyuqlikli hosilalar. | C25: 0 | D25: Qayta qidirish kerak | E25: pancreatic pseudocyst ultrasound; walled-off necrosis; pancreatic cystic lesions | F25: 2026-10-17
... A140: 09.27.10 | B140: 27.10. Yoshga bog‘liq normal o‘lchamlar va pediatrik xavfsizlik. | C140: 0 | D140: Qayta qidirish kerak | E140: pediatric ultrasound normal values organ size children | F140: 2026-10-17
A142: Bo‘limlar holati
A143: Bo‘lim | B143: Holat | C143: Izoh
A144: I. ULTRATOVUSH FIZIKASI VA APPARAT BILAN ISHLASH | B144: Ishlangan, yakunlanmagan | C144: Qisman mavzular qayta qidiruv navbatida
A145: II. TEKSHIRUV METODIKASI VA DIAGNOSTIK TAFAKKUR | B145: Ishlangan, yakunlanmagan | C145: Ochiq mavzular qayta qidiruv navbatida
A146: III. QORIN BO‘SHLIG‘I VA RETROPERITONEAL SOHA | B146: Ishlangan, yakunlanmagan | C146: Ochiq mavzular navbatda; ChatGPT 1-partiyasi qo‘shilgan
A147: IV. CHANOQ A’ZOLARI VA UROLOGIYA | B147: Ishlangan, yakunlanmagan | C147: Birinchi qidiruv 2026-10-17; natijalar videolar ko‘rilmaguncha tasdiqlanmagan
A148: V. AKUSHERLIK VA PERINATOLOGIYA | B148: Ishlangan, yakunlanmagan | C148: Birinchi qidiruv 2026-10-17; ochiq mavzular navbatda, boshqa tildagi zaxira bor
A149: VI. QALQONSIMON BEZ, SUT BEZI VA YUZAKI TUZILMALAR | B149: Ishlangan, yakunlanmagan | C149: Birinchi qidiruv 2026-10-17; sut bezi darslarining ko‘pi yopiq — qayta qidirish kerak
A150: VII. QON TOMIRLAR VA GEMODINAMIKA | B150: Ishlangan, yakunlanmagan | C150: Birinchi qidiruv 2026-10-17
A151: VIII. ECHOKARDIOGRAFIYA | B151: Ishlangan, yakunlanmagan | C151: Birinchi qidiruv 2026-10-17
A152: IX. PEDIATRIK ULTRATOVUSH | B152: Ishlangan, yakunlanmagan | C152: Birinchi qidiruv 2026-10-17; invaginatsiya va yoshga xos me’yorlar ochiq
A153: X. MUSKUL-SKELET VA YUMSHOQ TO‘QIMALAR | B153: Navbatda | C153: Hali ishlanmagan; ilova katalogi v1 darslari bor bo‘lishi mumkin
A154: XI. SHOSHILINCH UZI VA POCUS | B154: Navbatda | C154: Hali ishlanmagan; ilova katalogi v1 darslari bor bo‘lishi mumkin
... A156: XIII. SIFAT, RAQAMLI ISH JARAYONI VA KASBIY RIVOJLANISH | B156: Navbatda | C156: Hali ishlanmagan; ilova katalogi v1 darslari bor bo‘lishi mumkin

Sheet Boshqa til zaxirasi
A1: Kod | B1: YouTube URL | C1: Sarlavha | D1: Kanal | E1: Til | F1: Holat
A2: 04.16.09 | B2: https://www.youtube.com/watch?v=GgEFNTCF3hE | C2: Ultrassonografia na avaliação do DIU | D2: DrPixel - UNICAMP | E2: Portugal | F2: Havola tekshirilgan (oEmbed); oxirida to‘ldirish uchun zaxira, subtitr alohida tarjima qilinadi
A3: 04.17.05 | B3: https://www.youtube.com/watch?v=oUO9OtDKkIo | C3: Masas testiculares por ecografía. | D3: RadioLili - Radiología e Imágenes | E3: Ispan | F3: Havola tekshirilgan (oEmbed); oxirida to‘ldirish uchun zaxira, subtitr alohida tarjima qilinadi
A4: 05.19.01 | B4: https://www.youtube.com/watch?v=EHNIZ5YyVgw | C4: [GUIA ISUOG] Ecografía del primer trimestre del embarazo. | PARTE 2 | (AUDIO REMASTERIZADO) | D4: Pedro VargasMD | E4: Ispan | F4: Havola tekshirilgan (oEmbed); oxirida to‘ldirish uchun zaxira, subtitr alohida tarjima qilinadi
A5: 05.19.01 | B5: https://www.youtube.com/watch?v=oQkzUPrnVt8 | C5: Il Primo Trimestre: l'ecografia a 11-14 settimane - G. Grisolia | D5: Medicalchannel | E5: Italyan | F5: Havola tekshirilgan (oEmbed); oxirida to‘ldirish uchun zaxira, subtitr alohida tarjima qilinadi
A6: 05.20.11 | B6: https://www.youtube.com/watch?v=mS5n2wNjuDs | C6: SGA und fetale Wachstumsrestriktion – Diagnostik, Überwachung und Geburtsplanung | D6: Gynther | E6: Nemis | F6: Havola tekshirilgan (oEmbed); oxirida to‘ldirish uchun zaxira, subtitr alohida tarjima qilinadi
A7: 05.21.05 | B7: https://www.youtube.com/watch?v=yGlP6mraFsI | C7: ECO DOPPLER EN OBSTETRICIA: HIPOXIA, ARTERIAS UTERINAS, ANEMIA FETAL... | D7: aulaginecologia | E7: Ispan | F7: Havola tekshirilgan (oEmbed); oxirida to‘ldirish uchun zaxira, subtitr alohida tarjima qilinadi
A8: 05.21.03 | B8: https://www.youtube.com/watch?v=1RNmygm6Crs | C8: Medicina Fetal: Obtención de la onda de velocidad de flujo Doppler de la arteria cerebral media. | D8: Hector Quiroga | E8: Ispan | F8: Havola tekshirilgan (oEmbed); oxirida to‘ldirish uchun zaxira, subtitr alohida tarjima qilinadi
A9: 05.20.05 | B9: https://www.youtube.com/watch?v=G-LbrNbOd-Y | C9: ISUOG Guidelines: Fetal Heart Evaluation in the Second Trimester | D9: Ecocardiografía Fetal Dr. Montaño | E9: Noma’lum (nomi inglizcha, kanal ispancha) | F9: Havola tekshirilgan (oEmbed); oxirida to‘ldirish uchun zaxira, subtitr alohida tarjima qilinadi
A10: 06.22.07 | B10: https://www.youtube.com/watch?v=QiS7Xxya_2U | C10: FINE NEEDLE ASPIRATION OF THE THYROID | D10: Varisson Girişimsel Radyoloji | E10: Noma’lum (nomi inglizcha, kanal turkcha) | F10: Havola tekshirilgan (oEmbed); oxirida to‘ldirish uchun zaxira, subtitr alohida tarjima qilinadi

Sheet Katalog
A1: Video ID | B1: Asosiy kod | C1: Qo‘shimcha kodlar | D1: Kichik mavzu (asosiy kod) | E1: Video nomi | F1: YouTube URL | G1: Muallif / tashkilot | H1: Manba turi | I1: Davomiylik | J1: Nashr sanasi | K1: Asl tili | L1: O‘quv darajasi | M1: Nazariy / amaliy | N1: Subtitr (mavjudligi, turi) | O1: Dual Replay mosligi | P1: Tekshirilgan sana | Q1: Tekshiruv holati | R1: Mavzuga moslik | S1: Tibbiy ishonchlilik | T1: Amaliy demonstratsiya | U1: Tushuntirish sifati | V1: O‘quv darajasi (ball) | W1: Vizual aniqlik | X1: Jami (30) | Y1: Izoh
A2: V001 | B2: 03.10.01 | C2: 03.10.02 | D2: =IFERROR(INDEX(Mundarija!$D:$D,MATCH(B2,Mundarija!$A:$A,0)),"kod topilmadi") -> 10.1. Jigar segmentlari, normal anatomiyasi va o‘lchamlari. | E2: Liver: Anatomy, Physiology & Normal Ultrasound :: Unit 3 :: Abdominal Ultrasound with Sononerds | F2: https://www.youtube.com/watch?v=x6hXhLNc-jU | G2: Sononerds | H2: Ta’lim kanali (sonografiya kolleji kursi) | I2: 2:05:06 | J2: tekshirilmadi | K2: Ingliz | L2: Boshlang‘ich | M2: Nazariy + amaliy | N2: Tekshirilmagan | O2: Ingliz subtitri bo‘lsa mos (tekshirilmagan) | P2: 2026-10-17 | Q2: Havola tekshirilgan (oEmbed, GitHub serveri) | X2: =IF(COUNT(R2:W2)=6,SUM(R2:W2),"ko‘rilmagan") -> ko‘rilmagan | Y2: Ilovada: Qorin bo‘shlig‘i a’zolari → Jigar: anatomiya va segmentlar
A3: V002 | B3: 03.10.01 | D3: =IFERROR(INDEX(Mundarija!$D:$D,MATCH(B3,Mundarija!$A:$A,0)),"kod topilmadi") -> 10.1. Jigar segmentlari, normal anatomiyasi va o‘lchamlari. | E3: Ultrasound Couinaud's Liver Segments | F3: https://www.youtube.com/watch?v=JSUsM8aN1XU | G3: Sonographic Tendencies | H3: Ta’lim kanali (sonografist) | I3: 10:22 | J3: 2019-12-30 | K3: Ingliz | L3: Boshlang‘ich | M3: Amaliy | N3: Tekshirilmagan | O3: Ingliz subtitri bo‘lsa mos (tekshirilmagan) | P3: 2026-10-17 | Q3: Havola tekshirilgan (oEmbed, GitHub serveri) | X3: =IF(COUNT(R3:W3)=6,SUM(R3:W3),"ko‘rilmagan") -> ko‘rilmagan | Y3: Ilovada: Qorin bo‘shlig‘i a’zolari → Jigar: anatomiya va segmentlar
A4: V003 | B4: 03.10.02 | D4: =IFERROR(INDEX(Mundarija!$D:$D,MATCH(B4,Mundarija!$A:$A,0)),"kod topilmadi") -> 10.2. Jigarni standart tekshirish protokoli. | E4: Liver Ultrasound Protocol | F4: https://www.youtube.com/watch?v=GvvGZENUvWc | G4: Sonographic Tendencies | H4: Ta’lim kanali (sonografist) | I4: 7:26 | J4: 2017-10-08 | K4: Ingliz | L4: Boshlang‘ich | M4: Amaliy | N4: Tekshirilmagan | O4: Ingliz subtitri bo‘lsa mos (tekshirilmagan) | P4: 2026-10-17 | Q4: Havola tekshirilgan (oEmbed, GitHub serveri) | X4: =IF(COUNT(R4:W4)=6,SUM(R4:W4),"ko‘rilmagan") -> ko‘rilmagan | Y4: Ilovada: Qorin bo‘shlig‘i a’zolari → Jigar: tekshirish texnikasi
A5: V004 | B5: 03.11.06 | D5: =IFERROR(INDEX(Mundarija!$D:$D,MATCH(B5,Mundarija!$A:$A,0)),"kod topilmadi") -> 11.6. Umumiy o‘t yo‘li (CBD)ni turli kesimlarda topish va tekshirish. | E5: Hot Tips - Locating the Common Bile Duct with Ultrasound | F5: https://www.youtube.com/watch?v=U50O8_fsemY | G5: Gulfcoast Ultrasound Institute (Theresa Jorgensen) | H5: Ta’lim markazi | I5: 3:32 | J5: tekshirilmadi | K5: Ingliz | L5: O‘rta | M5: Amaliy | N5: Tekshirilmagan | O5: Ingliz subtitri bo‘lsa mos (tekshirilmagan) | P5: 2026-10-17 | Q5: Havola tekshirilgan (oEmbed, GitHub serveri) | X5: =IF(COUNT(R5:W5)=6,SUM(R5:W5),"ko‘rilmagan") -> ko‘rilmagan | Y5: Ilovada: Qorin bo‘shlig‘i a’zolari → O‘t pufagi va o‘t yo‘llari: anatomiya
A6: V005 | B6: 03.10.07 | C6: 12.30.06 | D6: =IFERROR(INDEX(Mundarija!$D:$D,MATCH(B6,Mundarija!$A:$A,0)),"kod topilmadi") -> 10.7. Jigar elastografiyasi: ko‘rsatmalar, texnika va cheklovlar. | E6: Ultrasound Elastography for Liver Fibrosis | F6: https://www.youtube.com/watch?v=eoze_8nUjfA | G6: Michigan Medicine | H6: Ta’lim kanali | I6: tekshirilmadi | J6: tekshirilmadi | K6: Ingliz | L6: O‘rta–ilg‘or | M6: Nazariy | N6: Tekshirilmagan | O6: Ingliz subtitri bo‘lsa mos (tekshirilmagan) | P6: 2026-10-17 | Q6: Havola tekshirilgan (oEmbed, GitHub serveri) | X6: =IF(COUNT(R6:W6)=6,SUM(R6:W6),"ko‘rilmagan") -> ko‘rilmagan | Y6: Faqat qidiruv natijasidan; kanal va mazmun tekshirilmagan; Ilovada: Qorin bo‘shlig‘i a’zolari → Jigar: elastografiya
A7: V006 | B7: 02.08.02 | C7: 01.02.02; 01.03.01; 02.08.03 | D7: =IFERROR(INDEX(Mundarija!$D:$D,MATCH(B7,Mundarija!$A:$A,0)),"kod topilmadi") -> 8.2. Bo‘ylama, ko‘ndalang va qiya tekisliklar. | E7: Basic Abdominal Ultrasound Imaging :: Unit 1 :: Normal Abdomen Ultrasound with Sononerds | F7: https://www.youtube.com/watch?v=3pIL7c-8UH8 | G7: Sononerds | H7: Ta’lim kanali (sonografiya kolleji kursi) | I7: 33:42 | J7: tekshirilmadi | K7: Ingliz | L7: Boshlang‘ich | M7: Nazariy | N7: Tekshirilmagan | O7: Ingliz subtitri bo‘lsa mos (tekshirilmagan) | P7: 2026-10-17 | Q7: Havola tekshirilgan (oEmbed, GitHub serveri) | X7: =IF(COUNT(R7:W7)=6,SUM(R7:W7),"ko‘rilmagan") -> ko‘rilmagan | Y7: Ilovada: Ultratovush asoslari: fizika va apparat → Qorin UZI asoslari: tekisliklar, datchik, atamalar
A8: V007 | B8: 03.15.04 | D8: =IFERROR(INDEX(Mundarija!$D:$D,MATCH(B8,Mundarija!$A:$A,0)),"kod topilmadi") -> 15.4. Erkin suyuqlik, peritoneal va mezenterial o‘zgarishlar. | E8: Body Systems & Cavities :: Unit 2 :: Normal Abdominal Ultrasound with Sononerds | F8: https://www.youtube.com/watch?v=luK0ElID9Hs | G8: Sononerds | H8: Ta’lim kanali (sonografiya kolleji kursi) | I8: 33:20 | J8: tekshirilmadi | K8: Ingliz | L8: Boshlang‘ich | M8: Nazariy | N8: Tekshirilmagan | O8: Ingliz subtitri bo‘lsa mos (tekshirilmagan) | P8: 2026-10-17 | Q8: Havola tekshirilgan (oEmbed, GitHub serveri) | X8: =IF(COUNT(R8:W8)=6,SUM(R8:W8),"ko‘rilmagan") -> ko‘rilmagan | Y8: Peritoneum va bo‘shliqlar anatomiyasi; patologiya yo‘q; Ilovada: Qorin bo‘shlig‘i a’zolari → Qorin bo‘shlig‘i anatomiyasi va qorin parda
A9: V008 | B9: 02.08.04 | D9: =IFERROR(INDEX(Mundarija!$D:$D,MATCH(B9,Mundarija!$A:$A,0)),"kod topilmadi") -> 8.4. Standart kesimlar va to‘liq tekshiruv protokollari. | E9: US Abdomen Complete Protocol | F9: https://www.youtube.com/watch?v=xLYBOf2da8s | G9: Sonographic Tendencies | H9: Ta’lim kanali (sonografist) | I9: 12:01 | J9: 2021-03-20 | K9: Ingliz | L9: Boshlang‘ich | M9: Amaliy | N9: Tekshirilmagan | O9: Ingliz subtitri bo‘lsa mos (tekshirilmagan) | P9: 2026-10-17 | Q9: Havola tekshirilgan (oEmbed, GitHub serveri) | X9: =IF(COUNT(R9:W9)=6,SUM(R9:W9),"ko‘rilmagan") -> ko‘rilmagan | Y9: Ilovada: Qorin bo‘shlig‘i a’zolari → To‘liq qorin protokoli
A10: V009 | B10: 03.10.04 | D10: =IFERROR(INDEX(Mundarija!$D:$D,MATCH(B10,Mundarija!$A:$A,0)),"kod topilmadi") -> 10.4. Portal gipertenziya, portal va jigar venalari. | E10: Portal Vein Doppler Protocol | F10: https://www.youtube.com/watch?v=SS-ATlJ9OCk | G10: Sonographic Tendencies | H10: Ta’lim kanali (sonografist) | I10: 12:48 | J10: 2019-12-16 | K10: Ingliz | L10: O‘rta | M10: Amaliy | N10: Tekshirilmagan | O10: Ingliz subtitri bo‘lsa mos (tekshirilmagan) | P10: 2026-10-17 | Q10: Havola tekshirilgan (oEmbed, GitHub serveri) | X10: =IF(COUNT(R10:W10)=6,SUM(R10:W10),"ko‘rilmagan") -> ko‘rilmagan | Y10: Ilovada: Qorin bo‘shlig‘i a’zolari → Darvoza venasi Doppleri
A11: V010 | B11: 03.12.01 | D11: =IFERROR(INDEX(Mundarija!$D:$D,MATCH(B11,Mundarija!$A:$A,0)),"kod topilmadi") -> 12.1. Normal anatomiya va vizualizatsiya usullari. | E11: Pancreas Sonoanatomy | F11: https://www.youtube.com/watch?v=yK_ETT0yZ5Q | G11: Sonographic Tendencies | H11: Ta’lim kanali (sonografist) | I11: 6:44 | J11: 2021-11-25 | K11: Ingliz | L11: Boshlang‘ich | M11: Amaliy | N11: Tekshirilmagan | O11: Ingliz subtitri bo‘lsa mos (tekshirilmagan) | P11: 2026-10-17 | Q11: Havola tekshirilgan (oEmbed, GitHub serveri) | X11: =IF(COUNT(R11:W11)=6,SUM(R11:W11),"ko‘rilmagan") -> ko‘rilmagan | Y11: Ilovada: Qorin bo‘shlig‘i a’zolari → Oshqozon osti bezi: tekshirish texnikasi
A12: V011 | B12: 03.14.01 | D12: =IFERROR(INDEX(Mundarija!$D:$D,MATCH(B12,Mundarija!$A:$A,0)),"kod topilmadi") -> 14.1. Buyrak anatomiyasi, o‘lchamlari va normal parenxima. | E12: Renal Ultrasound Protocol | F12: https://www.youtube.com/watch?v=8JjIbqp5kVI | G12: Sonographic Tendencies | H12: Ta’lim kanali (sonografist) | I12: 15:13 | J12: 2018-02-22 | K12: Ingliz | L12: Boshlang‘ich | M12: Amaliy | N12: Tekshirilmagan | O12: Ingliz subtitri bo‘lsa mos (tekshirilmagan) | P12: 2026-10-17 | Q12: Havola tekshirilgan (oEmbed, GitHub serveri) | X12: =IF(COUNT(R12:W12)=6,SUM(R12:W12),"ko‘rilmagan") -> ko‘rilmagan | Y12: Ilovada: Urologiya → Buyrak: tekshirish texnikasi
A13: V012 | B13: 03.14.03 | C13: 03.14.02; 03.14.04 | D13: =IFERROR(INDEX(Mundarija!$D:$D,MATCH(B13,Mundarija!$A:$A,0)),"kod topilmadi") -> 14.3. Nefrolitiaz va gidronefroz. | E13: Renal Pathology | F13: https://www.youtube.com/watch?v=LsK7ykAjHog | G13: Sonographic Tendencies | H13: Ta’lim kanali (sonografist) | I13: 30:35 | J13: tekshirilmadi | K13: Ingliz | L13: O‘rta | M13: Amaliy | N13: Tekshirilmagan | O13: Ingliz subtitri bo‘lsa mos (tekshirilmagan) | P13: 2026-10-17 | Q13: Havola tekshirilgan (oEmbed, GitHub serveri) | X13: =IF(COUNT(R13:W13)=6,SUM(R13:W13),"ko‘rilmagan") -> ko‘rilmagan | Y13: Ilovada: Urologiya → Buyrak: patologiya
A14: V013 | B14: 02.09.01 | C14: 03.10.03; 03.11.02; 03.12.02; 03.13.02; 03.14.03 | D14: =IFERROR(INDEX(Mundarija!$D:$D,MATCH(B14,Mundarija!$A:$A,0)),"kod topilmadi") -> 9.1. Normal anatomiyani patologiyadan farqlash. | E14: Abdominal Ultrasound Normal Vs Abnormal Images | Liver, Gallbladder, Pancreas, Kidney, Hernia USG | F14: https://www.youtube.com/watch?v=eSekFP_KIQk | G14: Dr. Sam’s Imaging Library | H14: Ta’lim kanali (tasvirlar to‘plami) | I14: 1:27:13 | J14: tekshirilmadi | K14: Ingliz | L14: O‘rta | M14: Tasvirlar galereyasi | N14: Tekshirilmagan | O14: Ingliz subtitri bo‘lsa mos (tekshirilmagan) | P14: 2026-10-17 | Q14: Havola tekshirilgan (oEmbed, GitHub serveri) | X14: =IF(COUNT(R14:W14)=6,SUM(R14:W14),"ko‘rilmagan") -> ko‘rilmagan | Y14: Takrorlash uchun; har bir patologiya qisqa; Ilovada: Qorin bo‘shlig‘i a’zolari → Normal va patologik tasvirlar (takrorlash)
A15: V014 | B15: 01.01.01 | D15: =IFERROR(INDEX(Mundarija!$D:$D,MATCH(B15,Mundarija!$A:$A,0)),"kod topilmadi") -> 1.1. Tovush va ultratovushning tabiati, chastota, davr, amplituda va to‘lqin uzunligi. | E15: Ultrasound Physics with Sononerds Unit 2 | F15: https://www.youtube.com/watch?v=c6PQzbzJgUg | G15: Sononerds | H15: Ta’lim kanali (sonografiya kolleji kursi, 25 qism) | I15: ~9:42 | J15: 2021-09-06 | K15: Ingliz | L15: Boshlang‘ich | M15: Nazariy | N15: Tekshirilmagan | O15: Ingliz subtitri bo‘lsa mos (tekshirilmagan) | P15: 2026-10-17 | Q15: Havola tekshirilgan (oEmbed, GitHub serveri) | X15: =IF(COUNT(R15:W15)=6,SUM(R15:W15),"ko‘rilmagan") -> ko‘rilmagan | Y15: Tovush to‘lqini, to‘lqin turlari, akustik parametrlar; Ilovada: Ultratovush asoslari: fizika va apparat → Fizika: tovush to‘lqini va parametrlari
A16: V015 | B16: 01.01.01 | D16: =IFERROR(INDEX(Mundarija!$D:$D,MATCH(B16,Mundarija!$A:$A,0)),"kod topilmadi") -> 1.1. Tovush va ultratovushning tabiati, chastota, davr, amplituda va to‘lqin uzunligi. | E16: Ultrasound Physics with Sononerds Unit 3 | F16: https://www.youtube.com/watch?v=UFU9zVAa6WM | G16: Sononerds | H16: Ta’lim kanali (sonografiya kolleji kursi, 25 qism) | I16: ~1:08 | J16: 2021-09-06 | K16: Ingliz | L16: Boshlang‘ich | M16: Nazariy | N16: Tekshirilmagan | O16: Ingliz subtitri bo‘lsa mos (tekshirilmagan) | P16: 2026-10-17 | Q16: Havola tekshirilgan (oEmbed, GitHub serveri) | X16: =IF(COUNT(R16:W16)=6,SUM(R16:W16),"ko‘rilmagan") -> ko‘rilmagan | Y16: Davr, chastota, tezlik, to‘lqin uzunligi, amplituda, quvvat, intensivlik; Ilovada: Ultratovush asoslari: fizika va apparat → Fizika: tovush to‘lqini va parametrlari
A17: V016 | B17: 01.01.01 | D17: =IFERROR(INDEX(Mundarija!$D:$D,MATCH(B17,Mundarija!$A:$A,0)),"kod topilmadi") -> 1.1. Tovush va ultratovushning tabiati, chastota, davr, amplituda va to‘lqin uzunligi. | E17: Ultrasound Physics 1 - Sound as Waves | F17: https://www.youtube.com/watch?v=jv748J0XB-0 | G17: Marc Kohli | H17: Shaxsiy kanal (radiolog) | I17: 2:40 | J17: 2012-06-19 | K17: Ingliz | L17: Boshlang‘ich | M17: Nazariy | N17: Tekshirilmagan | O17: Ingliz subtitri bo‘lsa mos (tekshirilmagan) | P17: 2026-10-17 | Q17: Havola tekshirilgan (oEmbed, GitHub serveri) | X17: =IF(COUNT(R17:W17)=6,SUM(R17:W17),"ko‘rilmagan") -> ko‘rilmagan | Y17: Qisqa kirish; Ilovada: Ultratovush asoslari: fizika va apparat → Fizika: tovush to‘lqini va parametrlari
A18: V017 | B18: 01.01.02 | C18: 01.01.03 | D18: =IFERROR(INDEX(Mundarija!$D:$D,MATCH(B18,Mundarija!$A:$A,0)),"kod topilmadi") -> 1.2. Tovush tezligi, akustik impedans va to‘qimalar chegarasida aks etish. | E18: Ultrasound Physics with Sononerds Unit 6b | F18: https://www.youtube.com/watch?v=htzA4DUZz_s | G18: Sononerds | H18: Ta’lim kanali (sonografiya kolleji kursi, 25 qism) | I18: 58:17 | J18: 2021-09-22 | K18: Ingliz | L18: Boshlang‘ich–o‘rta | M18: Nazariy | N18: Tekshirilmagan | O18: Ingliz subtitri bo‘lsa mos (tekshirilmagan) | P18: 2026-10-17 | Q18: Havola tekshirilgan (oEmbed, GitHub serveri) | X18: =IF(COUNT(R18:W18)=6,SUM(R18:W18),"ko‘rilmagan") -> ko‘rilmagan | Y18: Aks-sado: refleksiya, sochilish, refraksiya, normal va qiya tushish; Ilovada: Ultratovush asoslari: fizika va apparat → Fizika: akustik impedans va aks-sado
A19: V018 | B19: 01.01.02 | D19: =IFERROR(INDEX(Mundarija!$D:$D,MATCH(B19,Mundarija!$A:$A,0)),"kod topilmadi") -> 1.2. Tovush tezligi, akustik impedans va to‘qimalar chegarasida aks etish. | E19: Acoustic Impedance and Reflection Explained | Radiology Ultrasound Physics | F19: https://www.youtube.com/watch?v=-zXuz0mqe_Q | G19: Radiology Tutorials | H19: Ta’lim kanali (radiologiya fizikasi) | I19: tekshirilmadi | J19: 2026-04-22 | K19: Ingliz | L19: Boshlang‘ich | M19: Nazariy | N19: Tekshirilmagan | O19: Ingliz subtitri bo‘lsa mos (tekshirilmagan) | P19: 2026-10-17 | Q19: Havola tekshirilgan (oEmbed, GitHub serveri) | X19: =IF(COUNT(R19:W19)=6,SUM(R19:W19),"ko‘rilmagan") -> ko‘rilmagan | Y19: Ilovada: Ultratovush asoslari: fizika va apparat → Fizika: akustik impedans va aks-sado
A20: V019 | B20: 01.01.03 | C20: 01.01.02 | D20: =IFERROR(INDEX(Mundarija!$D:$D,MATCH(B20,Mundarija!$A:$A,0)),"kod topilmadi") -> 1.3. Refleksiya, refraksiya, sochilish, diffraksiya va absorbsiya. | E20: Ultrasound Physics 2 - Interactions with Tissue | F20: https://www.youtube.com/watch?v=Q1YPZ-04dag | G20: Marc Kohli | H20: Shaxsiy kanal (radiolog) | I20: tekshirilmadi | J20: 2012-06-19 | K20: Ingliz | L20: Boshlang‘ich | M20: Nazariy | N20: Tekshirilmagan | O20: Ingliz subtitri bo‘lsa mos (tekshirilmagan) | P20: 2026-10-17 | Q20: Havola tekshirilgan (oEmbed, GitHub serveri) | X20: =IF(COUNT(R20:W20)=6,SUM(R20:W20),"ko‘rilmagan") -> ko‘rilmagan | Y20: Muallif tavsifida xato tuzatilgan: spekulyar aks silliq yuzada bo‘ladi; Ilovada: Ultratovush asoslari: fizika va apparat → Fizika: akustik impedans va aks-sado
A21: V020 | B21: 01.01.04 | D21: =IFERROR(INDEX(Mundarija!$D:$D,MATCH(B21,Mundarija!$A:$A,0)),"kod topilmadi") -> 1.4. Attenuatsiya, chuqurlik va chastota o‘rtasidagi bog‘liqlik. | E21: Ultrasound Physics with Sononerds Unit 6a | F21: https://www.youtube.com/watch?v=77LZeskg4Eg | G21: Sononerds | H21: Ta’lim kanali (sonografiya kolleji kursi, 25 qism) | I21: >1:26 | J21: 2021-09-20 | K21: Ingliz | L21: O‘rta | M21: Nazariy | N21: Tekshirilmagan | O21: Ingliz subtitri bo‘lsa mos (tekshirilmagan) | P21: 2026-10-17 | Q21: Havola tekshirilgan (oEmbed, GitHub serveri) | X21: =IF(COUNT(R21:W21)=6,SUM(R21:W21),"ko‘rilmagan") -> ko‘rilmagan | Y21: Attenuatsiya, desibellar, yarim qatlam qalinligi; Ilovada: Ultratovush asoslari: fizika va apparat → Fizika: attenuatsiya
A22: V021 | B22: 01.02.05 | C22: 01.01.05 | D22: =IFERROR(INDEX(Mundarija!$D:$D,MATCH(B22,Mundarija!$A:$A,0)),"kod topilmadi") -> 2.5. B-rejim, M-rejim va tasvirni qayta ishlash. | E22: Ultrasound Physics with Sononerds Unit 11 | F22: https://www.youtube.com/watch?v=TSHVXMbS2jM | G22: Sononerds | H22: Ta’lim kanali (sonografiya kolleji kursi, 25 qism) | I22: >14:20 | J22: 2021-10-25 | K22: Ingliz | L22: Boshlang‘ich | M22: Nazariy | N22: Tekshirilmagan | O22: Ingliz subtitri bo‘lsa mos (tekshirilmagan) | P22: 2026-10-17 | Q22: Havola tekshirilgan (oEmbed, GitHub serveri) | X22: =IF(COUNT(R22:W22)=6,SUM(R22:W22),"ko‘rilmagan") -> ko‘rilmagan | Y22: A, B va M rejim; Ilovada: Ultratovush asoslari: fizika va apparat → A, B, M rejimlar va apparat tuzilishi
A23: V022 | B23: 01.02.01 | C23: 01.02.07 | D23: =IFERROR(INDEX(Mundarija!$D:$D,MATCH(B23,Mundarija!$A:$A,0)),"kod topilmadi") -> 2.1. Pyezoelektrik effekt va transduserning ishlash prinsipi. | E23: Ultrasound Physics with Sononerds Unit 8 | F23: https://www.youtube.com/watch?v=HC_tHnNZJ-Q | G23: Sononerds | H23: Ta’lim kanali (sonografiya kolleji kursi, 25 qism) | I23: 48:51 | J23: 2021-09-27 | K23: Ingliz | L23: Boshlang‘ich–o‘rta | M23: Nazariy | N23: Tekshirilmagan | O23: Ingliz subtitri bo‘lsa mos (tekshirilmagan) | P23: 2026-10-17 | Q23: Havola tekshirilgan (oEmbed, GitHub serveri) | X23: =IF(COUNT(R23:W23)=6,SUM(R23:W23),"ko‘rilmagan") -> ko‘rilmagan | Y23: PZT element, moslovchi qatlam, datchikni tozalash (8.5.1); Ilovada: Ultratovush asoslari: fizika va apparat → Datchik: pyezoelement va tuzilishi
A24: V023 | B24: 01.02.02 | C24: 01.02.03 | D24: =IFERROR(INDEX(Mundarija!$D:$D,MATCH(B24,Mundarija!$A:$A,0)),"kod topilmadi") -> 2.2. Konveks, chiziqli, sektor/fazalangan va endokavitar datchiklar. | E24: Ultrasound Physics with Sononerds Unit 12a | F24: https://www.youtube.com/watch?v=QzZEKS1x0l8 | G24: Sononerds | H24: Ta’lim kanali (sonografiya kolleji kursi, 25 qism) | I24: >1:18 | J24: 2021-11-01 | K24: Ingliz | L24: O‘rta | M24: Nazariy | N24: Tekshirilmagan | O24: Ingliz subtitri bo‘lsa mos (tekshirilmagan) | P24: 2026-10-17 | Q24: Havola tekshirilgan (oEmbed, GitHub serveri) | X24: =IF(COUNT(R24:W24)=6,SUM(R24:W24),"ko‘rilmagan") -> ko‘rilmagan | Y24: Massivlar, fokuslash, burish; chiziqli, konveks, fazalangan, 3D datchiklar; Ilovada: Ultratovush asoslari: fizika va apparat → Datchik turlari
A25: V024 | B25: 01.02.02 | D25: =IFERROR(INDEX(Mundarija!$D:$D,MATCH(B25,Mundarija!$A:$A,0)),"kod topilmadi") -> 2.2. Konveks, chiziqli, sektor/fazalangan va endokavitar datchiklar. | E25: Ultrasound Transducers | F25: https://www.youtube.com/watch?v=C0OFM297MlU | G25: Ultrasound Board Review | H25: Imtihonga tayyorlov kanali | I25: tekshirilmadi | J25: 2023-02-24 | K25: Ingliz | L25: Boshlang‘ich | M25: Nazariy | N25: Tekshirilmagan | O25: Ingliz subtitri bo‘lsa mos (tekshirilmagan) | P25: 2026-10-17 | Q25: Ishlamaydi: serverda “video mavjud emas” (2026-10-17) | X25: =IF(COUNT(R25:W25)=6,SUM(R25:W25),"ko‘rilmagan") -> ko‘rilmagan | Y25: Ilovadan olib tashlandi, o‘rniga boshqa dars qo‘yildi
A26: V025 | B26: 01.02.04 | C26: 01.03.02 | D26: =IFERROR(INDEX(Mundarija!$D:$D,MATCH(B26,Mundarija!$A:$A,0)),"kod topilmadi") -> 2.4. Eksenel, lateral va elevatsion rezolyutsiya. | E26: Ultrasound Physics with Sononerds Unit 10 | F26: https://www.youtube.com/watch?v=iLVeRa95WQc | G26: Sononerds | H26: Ta’lim kanali (sonografiya kolleji kursi, 25 qism) | I26: >48:18 | J26: 2021-10-11 | K26: Ingliz | L26: O‘rta | M26: Nazariy | N26: Tekshirilmagan | O26: Ingliz subtitri bo‘lsa mos (tekshirilmagan) | P26: 2026-10-17 | Q26: Havola tekshirilgan (oEmbed, GitHub serveri) | X26: =IF(COUNT(R26:W26)=6,SUM(R26:W26),"ko‘rilmagan") -> ko‘rilmagan | Y26: Aksial va lateral rezolyutsiya, fokuslash; Ilovada: Ultratovush asoslari: fizika va apparat → Rezolyutsiya: aksial, lateral, elevatsion
A27: V026 | B27: 01.02.04 | C27: 01.04.04 | D27: =IFERROR(INDEX(Mundarija!$D:$D,MATCH(B27,Mundarija!$A:$A,0)),"kod topilmadi") -> 2.4. Eksenel, lateral va elevatsion rezolyutsiya. | E27: Ultrasound Physics with Sononerds Unit 12b | F27: https://www.youtube.com/watch?v=0rmwXyPXwhs | G27: Sononerds | H27: Ta’lim kanali (sonografiya kolleji kursi, 25 qism) | I27: 15:59 | J27: 2021-11-06 | K27: Ingliz | L27: O‘rta | M27: Nazariy | N27: Tekshirilmagan | O27: Ingliz subtitri bo‘lsa mos (tekshirilmagan) | P27: 2026-10-17 | Q27: Havola tekshirilgan (oEmbed, GitHub serveri) | X27: =IF(COUNT(R27:W27)=6,SUM(R27:W27),"ko‘rilmagan") -> ko‘rilmagan | Y27: Elevatsion rezolyutsiya, yon loblar; Ilovada: Ultratovush asoslari: fizika va apparat → Rezolyutsiya: aksial, lateral, elevatsion
A28: V027 | B28: 01.02.04 | D28: =IFERROR(INDEX(Mundarija!$D:$D,MATCH(B28,Mundarija!$A:$A,0)),"kod topilmadi") -> 2.4. Eksenel, lateral va elevatsion rezolyutsiya. | E28: Ultrasound Physics with Sononerds Unit 15b | F28: https://www.youtube.com/watch?v=EvZSiMTiePI | G28: Sononerds | H28: Ta’lim kanali (sonografiya kolleji kursi, 25 qism) | I28: tekshirilmadi | J28: 2021-11-15 | K28: Ingliz | L28: O‘rta | M28: Nazariy | N28: Tekshirilmagan | O28: Ingliz subtitri bo‘lsa mos (tekshirilmagan) | P28: 2026-10-17 | Q28: Havola tekshirilgan (oEmbed, GitHub serveri) | X28: =IF(COUNT(R28:W28)=6,SUM(R28:W28),"ko‘rilmagan") -> ko‘rilmagan | Y28: Fazoviy va kontrast rezolyutsiya; Ilovada: Ultratovush asoslari: fizika va apparat → Rezolyutsiya: aksial, lateral, elevatsion
A29: V028 | B29: 01.02.05 | C29: 01.03.04; 13.33.04; 02.09.07 | D29: =IFERROR(INDEX(Mundarija!$D:$D,MATCH(B29,Mundarija!$A:$A,0)),"kod topilmadi") -> 2.5. B-rejim, M-rejim va tasvirni qayta ishlash. | E29: Ultrasound Physics with Sononerds Unit 14 | F29: https://www.youtube.com/watch?v=UYtaDkhVrmQ | G29: Sononerds | H29: Ta’lim kanali (sonografiya kolleji kursi, 25 qism) | I29: 1:15:49 | J29: 2021-11-14 | K29: Ingliz | L29: O‘rta | M29: Nazariy | N29: Tekshirilmagan | O29: Ingliz subtitri bo‘lsa mos (tekshirilmagan) | P29: 2026-10-17 | Q29: Havola tekshirilgan (oEmbed, GitHub serveri) | X29: =IF(COUNT(R29:W29)=6,SUM(R29:W29),"ko‘rilmagan") -> ko‘rilmagan | Y29: Apparat tarkibi: qabul qilgich, kuchaytirish, kompensatsiya, PACS/DICOM; Ilovada: Ultratovush asoslari: fizika va apparat → A, B, M rejimlar va apparat tuzilishi
A30: V029 | B30: 01.03.03 | C30: 01.02.05 | D30: =IFERROR(INDEX(Mundarija!$D:$D,MATCH(B30,Mundarija!$A:$A,0)),"kod topilmadi") -> 3.3. Dynamic range, chastota, frame rate va tasvir tezligi. | E30: Ultrasound Physics with Sononerds Unit 16 | F30: https://www.youtube.com/watch?v=_8R-IiuLM0k | G30: Sononerds | H30: Ta’lim kanali (sonografiya kolleji kursi, 25 qism) | I30: >22:47 | J30: 2021-11-29 | K30: Ingliz | L30: O‘rta | M30: Nazariy | N30: Tekshirilmagan | O30: Ingliz subtitri bo‘lsa mos (tekshirilmagan) | P30: 2026-10-17 | Q30: Havola tekshirilgan (oEmbed, GitHub serveri) | X30: =IF(COUNT(R30:W30)=6,SUM(R30:W30),"ko‘rilmagan") -> ko‘rilmagan | Y30: Kompressiya (dynamic range); Ilovada: Ultratovush asoslari: fizika va apparat → Tasvirni sozlash: kompressiya (dynamic range)
A31: V030 | B31: 01.02.06 | D31: =IFERROR(INDEX(Mundarija!$D:$D,MATCH(B31,Mundarija!$A:$A,0)),"kod topilmadi") -> 2.6. Panoramik tasvir, compound imaging, harmonic imaging va speklni kamaytirish. | E31: Ultrasound Physics with Sononerds Unit 17a | F31: https://www.youtube.com/watch?v=8nS4NYD_LnU | G31: Sononerds | H31: Ta’lim kanali (sonografiya kolleji kursi, 25 qism) | I31: >25:07 | J31: 2021-11-29 | K31: Ingliz | L31: O‘rta | M31: Nazariy | N31: Tekshirilmagan | O31: Ingliz subtitri bo‘lsa mos (tekshirilmagan) | P31: 2026-10-17 | Q31: Havola tekshirilgan (oEmbed, GitHub serveri) | X31: =IF(COUNT(R31:W31)=6,SUM(R31:W31),"ko‘rilmagan") -> ko‘rilmagan | Y31: Garmonik tasvirlash; kompaund va panoramik yo‘q; Ilovada: Ultratovush asoslari: fizika va apparat → Garmonik tasvirlash
A32: V031 | B32: 01.02.07 | C32: 01.06.05 | D32: =IFERROR(INDEX(Mundarija!$D:$D,MATCH(B32,Mundarija!$A:$A,0)),"kod topilmadi") -> 2.7. Datchiklarni tozalash, dezinfeksiya va infeksiya nazorati. | E32: Proper POCUS Cleaning and Disinfection | F32: https://www.youtube.com/watch?v=mKomnw4PEwE | G32: USF Emergency Ultrasound | H32: Universitet (shoshilinch tibbiyot) | I32: 7:39 | J32: 2024-10-13 | K32: Ingliz | L32: Boshlang‘ich | M32: Amaliy | N32: Tekshirilmagan | O32: Ingliz subtitri bo‘lsa mos (tekshirilmagan) | P32: 2026-10-17 | Q32: Havola tekshirilgan (oEmbed, GitHub serveri) | X32: =IF(COUNT(R32:W32)=6,SUM(R32:W32),"ko‘rilmagan") -> ko‘rilmagan | Y32: Endokavitar datchik uchun yuqori darajali dezinfeksiya alohida tekshirilsin; Ilovada: Ultratovush asoslari: fizika va apparat → Datchikni tozalash va dezinfeksiya
A33: V032 | B33: 01.03.01 | D33: =IFERROR(INDEX(Mundarija!$D:$D,MATCH(B33,Mundarija!$A:$A,0)),"kod topilmadi") -> 3.1. Gain va TGC. | E33: Ultrasound 5 - Knobology 1 - Gain | F33: https://www.youtube.com/watch?v=z6n7C_4rHhk | G33: Marc Kohli | H33: Shaxsiy kanal (radiolog) | I33: tekshirilmadi | J33: 2012-06-30 | K33: Ingliz | L33: Boshlang‘ich | M33: Amaliy | N33: Tekshirilmagan | O33: Ingliz subtitri bo‘lsa mos (tekshirilmagan) | P33: 2026-10-17 | Q33: Havola tekshirilgan (oEmbed, GitHub serveri) | X33: =IF(COUNT(R33:W33)=6,SUM(R33:W33),"ko‘rilmagan") -> ko‘rilmagan | Y33: Ilovada: Ultratovush asoslari: fizika va apparat → Tasvirni sozlash: gain va TGC
A34: V033 | B34: 01.03.01 | C34: 01.03.02 | D34: =IFERROR(INDEX(Mundarija!$D:$D,MATCH(B34,Mundarija!$A:$A,0)),"kod topilmadi") -> 3.1. Gain va TGC. | E34: KNOBOLOGY 2: Focus, Gain, Frequency, Depth and Zoom | F34: https://www.youtube.com/watch?v=hMPA6hVPh0A | G34: msksono | H34: Ta’lim kanali (MSK sonografiya) | I34: >3:14 | J34: 2024-12-02 | K34: Ingliz | L34: Boshlang‘ich | M34: Amaliy | N34: Tekshirilmagan | O34: Ingliz subtitri bo‘lsa mos (tekshirilmagan) | P34: 2026-10-17 | Q34: Havola tekshirilgan (oEmbed, GitHub serveri) | X34: =IF(COUNT(R34:W34)=6,SUM(R34:W34),"ko‘rilmagan") -> ko‘rilmagan | Y34: Ilovada: Ultratovush asoslari: fizika va apparat → Tasvirni sozlash: gain va TGC
A35: V034 | B35: 01.03.02 | C35: 01.03.03 | D35: =IFERROR(INDEX(Mundarija!$D:$D,MATCH(B35,Mundarija!$A:$A,0)),"kod topilmadi") -> 3.2. Depth, fokus va ko‘rish maydoni. | E35: Ultrasound 6 - Knobology 2 - Focus, Field of View, Frame Rate | F35: https://www.youtube.com/watch?v=x8suZz5FeuM | G35: Marc Kohli | H35: Shaxsiy kanal (radiolog) | I35: 4:59 | J35: 2012-07-01 | K35: Ingliz | L35: Boshlang‘ich | M35: Amaliy | N35: Tekshirilmagan | O35: Ingliz subtitri bo‘lsa mos (tekshirilmagan) | P35: 2026-10-17 | Q35: Havola tekshirilgan (oEmbed, GitHub serveri) | X35: =IF(COUNT(R35:W35)=6,SUM(R35:W35),"ko‘rilmagan") -> ko‘rilmagan | Y35: Ilovada: Ultratovush asoslari: fizika va apparat → Tasvirni sozlash: chuqurlik, fokus, kadr tezligi
A36: V035 | B36: 01.03.02 | C36: 01.02.04 | D36: =IFERROR(INDEX(Mundarija!$D:$D,MATCH(B36,Mundarija!$A:$A,0)),"kod topilmadi") -> 3.2. Depth, fokus va ko‘rish maydoni. | E36: Ultrasound Physics with Sononerds Unit 9 | F36: https://www.youtube.com/watch?v=AvbdjCMA8OU | G36: Sononerds | H36: Ta’lim kanali (sonografiya kolleji kursi, 25 qism) | I36: >56:13 | J36: 2021-10-03 | K36: Ingliz | L36: O‘rta | M36: Nazariy | N36: Tekshirilmagan | O36: Ingliz subtitri bo‘lsa mos (tekshirilmagan) | P36: 2026-10-17 | Q36: Havola tekshirilgan (oEmbed, GitHub serveri) | X36: =IF(COUNT(R36:W36)=6,SUM(R36:W36),"ko‘rilmagan") -> ko‘rilmagan | Y36: Nur zonalari, fokus, divergensiya; Ilovada: Ultratovush asoslari: fizika va apparat → Ultratovush nuri va fokus
A37: V036 | B37: 01.03.02 | D37: =IFERROR(INDEX(Mundarija!$D:$D,MATCH(B37,Mundarija!$A:$A,0)),"kod topilmadi") -> 3.2. Depth, fokus va ko‘rish maydoni. | E37: Ultrasound Physics 4 - Beam Geometry | F37: https://www.youtube.com/watch?v=imM2qJY_bEI | G37: Marc Kohli | H37: Shaxsiy kanal (radiolog) | I37: tekshirilmadi | J37: 2012-06-30 | K37: Ingliz | L37: Boshlang‘ich | M37: Nazariy | N37: Tekshirilmagan | O37: Ingliz subtitri bo‘lsa mos (tekshirilmagan) | P37: 2026-10-17 | Q37: Havola tekshirilgan (oEmbed, GitHub serveri) | X37: =IF(COUNT(R37:W37)=6,SUM(R37:W37),"ko‘rilmagan") -> ko‘rilmagan | Y37: Ilovada: Ultratovush asoslari: fizika va apparat → Ultratovush nuri va fokus
A38: V037 | B38: 01.03.03 | D38: =IFERROR(INDEX(Mundarija!$D:$D,MATCH(B38,Mundarija!$A:$A,0)),"kod topilmadi") -> 3.3. Dynamic range, chastota, frame rate va tasvir tezligi. | E38: Physics with Sononerds Unit 13 | F38: https://www.youtube.com/watch?v=48m-hcI8i1g | G38: Sononerds | H38: Ta’lim kanali (sonografiya kolleji kursi, 25 qism) | I38: >1:01:35 | J38: 2021-10-26 | K38: Ingliz | L38: O‘rta | M38: Nazariy | N38: Tekshirilmagan | O38: Ingliz subtitri bo‘lsa mos (tekshirilmagan) | P38: 2026-10-17 | Q38: Havola tekshirilgan (oEmbed, GitHub serveri) | X38: =IF(COUNT(R38:W38)=6,SUM(R38:W38),"ko‘rilmagan") -> ko‘rilmagan | Y38: Kadr tezligi, vaqt rezolyutsiyasi; Ilovada: Ultratovush asoslari: fizika va apparat → Tasvirni sozlash: chuqurlik, fokus, kadr tezligi
